TESTS WITH ERRORS 
test10_DFS_Hanoi_02 (gradingtests.UnitTests)
Traceback (most recent call last):
  File "C:\Users\kille\academics\automatedgradingapp\app\testing\uninformed-solvers\gradingtests.py", line 246, in test10_DFS_Hanoi_02
    [20, ((2,5,), (4,), (1, 3))],
  File "C:\Users\kille\academics\automatedgradingapp\app\testing\uninformed-solvers\gradingtests.py", line 52, in runPlayXSteps
    results = self.pool.apply_async(self.playXSteps, [solver, plays]).get(timeout)
  File "C:\Program Files\Python37\lib\multiprocessing\pool.py", line 683, in get
    raise self._value
  File "C:\Program Files\Python37\lib\multiprocessing\pool.py", line 121, in worker
    result = (True, func(*args, **kwds))
  File "C:\Users\kille\academics\automatedgradingapp\app\testing\uninformed-solvers\gradingtests.py", line 27, in playXSteps
    solver.solveOneStep()
  File "C:\Users\kille\academics\automatedgradingapp\app\testing\uninformed-solvers\student_code_uninformed_solvers.py", line 42, in solveOneStep
    self.solveOneStep()
  File "C:\Users\kille\academics\automatedgradingapp\app\testing\uninformed-solvers\student_code_uninformed_solvers.py", line 40, in solveOneStep
    self.gm.reverseMove(self.currentState.requiredMovable)
  File "C:\Users\kille\academics\automatedgradingapp\app\testing\uninformed-solvers\student_code_game_masters.py", line 191, in reverseMove
    pred = movable_statement.predicate
AttributeError: 'NoneType' object has no attribute 'predicate'

test13_BFS_Hanoi_02 (gradingtests.UnitTests)
Traceback (most recent call last):
  File "C:\Users\kille\academics\automatedgradingapp\app\testing\uninformed-solvers\gradingtests.py", line 296, in test13_BFS_Hanoi_02
    [23, ((5,), (4,), (1, 2, 3))],
  File "C:\Users\kille\academics\automatedgradingapp\app\testing\uninformed-solvers\gradingtests.py", line 52, in runPlayXSteps
    results = self.pool.apply_async(self.playXSteps, [solver, plays]).get(timeout)
  File "C:\Program Files\Python37\lib\multiprocessing\pool.py", line 683, in get
    raise self._value
  File "C:\Program Files\Python37\lib\multiprocessing\pool.py", line 121, in worker
    result = (True, func(*args, **kwds))
  File "C:\Users\kille\academics\automatedgradingapp\app\testing\uninformed-solvers\gradingtests.py", line 27, in playXSteps
    solver.solveOneStep()
  File "C:\Users\kille\academics\automatedgradingapp\app\testing\uninformed-solvers\student_code_uninformed_solvers.py", line 114, in solveOneStep
    nextState = self.orderedStates.pop(0)
IndexError: pop from empty list

test14_BFS_Hanoi_03 (gradingtests.UnitTests)
Traceback (most recent call last):
  File "C:\Users\kille\academics\automatedgradingapp\app\testing\uninformed-solvers\gradingtests.py", line 314, in test14_BFS_Hanoi_03
    [23, ((1, 4, 5), (), (2, 3))],
  File "C:\Users\kille\academics\automatedgradingapp\app\testing\uninformed-solvers\gradingtests.py", line 52, in runPlayXSteps
    results = self.pool.apply_async(self.playXSteps, [solver, plays]).get(timeout)
  File "C:\Program Files\Python37\lib\multiprocessing\pool.py", line 683, in get
    raise self._value
  File "C:\Program Files\Python37\lib\multiprocessing\pool.py", line 121, in worker
    result = (True, func(*args, **kwds))
  File "C:\Users\kille\academics\automatedgradingapp\app\testing\uninformed-solvers\gradingtests.py", line 27, in playXSteps
    solver.solveOneStep()
  File "C:\Users\kille\academics\automatedgradingapp\app\testing\uninformed-solvers\student_code_uninformed_solvers.py", line 114, in solveOneStep
    nextState = self.orderedStates.pop(0)
IndexError: pop from empty list

test15_DFS_8Puzzle_01 (gradingtests.UnitTests)
Traceback (most recent call last):
  File "C:\Users\kille\academics\automatedgradingapp\app\testing\uninformed-solvers\gradingtests.py", line 52, in runPlayXSteps
    results = self.pool.apply_async(self.playXSteps, [solver, plays]).get(timeout)
  File "C:\Program Files\Python37\lib\multiprocessing\pool.py", line 679, in get
    raise TimeoutError
multiprocessing.context.TimeoutError

During handling of the above exception, another exception occurred:

Traceback (most recent call last):
  File "C:\Users\kille\academics\automatedgradingapp\app\testing\uninformed-solvers\gradingtests.py", line 333, in test15_DFS_8Puzzle_01
    [20, ((-1, 1, 4), (5, 2, 3), (6, 7, 8))],
  File "C:\Users\kille\academics\automatedgradingapp\app\testing\uninformed-solvers\gradingtests.py", line 57, in runPlayXSteps
    raise Exception("Timed out: %s" % inspect.stack()[1][3])
Exception: Timed out: test15_DFS_8Puzzle_01

test16_DFS_8Puzzle_02 (gradingtests.UnitTests)
Traceback (most recent call last):
  File "C:\Users\kille\academics\automatedgradingapp\app\testing\uninformed-solvers\gradingtests.py", line 52, in runPlayXSteps
    results = self.pool.apply_async(self.playXSteps, [solver, plays]).get(timeout)
  File "C:\Program Files\Python37\lib\multiprocessing\pool.py", line 679, in get
    raise TimeoutError
multiprocessing.context.TimeoutError

During handling of the above exception, another exception occurred:

Traceback (most recent call last):
  File "C:\Users\kille\academics\automatedgradingapp\app\testing\uninformed-solvers\gradingtests.py", line 352, in test16_DFS_8Puzzle_02
    [30, ((8, 1, -1), (7, 2, 3), (6, 5, 4))],
  File "C:\Users\kille\academics\automatedgradingapp\app\testing\uninformed-solvers\gradingtests.py", line 57, in runPlayXSteps
    raise Exception("Timed out: %s" % inspect.stack()[1][3])
Exception: Timed out: test16_DFS_8Puzzle_02

test17_DFS_8Puzzle_03 (gradingtests.UnitTests)
Traceback (most recent call last):
  File "C:\Users\kille\academics\automatedgradingapp\app\testing\uninformed-solvers\gradingtests.py", line 52, in runPlayXSteps
    results = self.pool.apply_async(self.playXSteps, [solver, plays]).get(timeout)
  File "C:\Program Files\Python37\lib\multiprocessing\pool.py", line 679, in get
    raise TimeoutError
multiprocessing.context.TimeoutError

During handling of the above exception, another exception occurred:

Traceback (most recent call last):
  File "C:\Users\kille\academics\automatedgradingapp\app\testing\uninformed-solvers\gradingtests.py", line 371, in test17_DFS_8Puzzle_03
    [8, ((8, 3, 4), (2, -1, 1), (7, 6, 5))],
  File "C:\Users\kille\academics\automatedgradingapp\app\testing\uninformed-solvers\gradingtests.py", line 57, in runPlayXSteps
    raise Exception("Timed out: %s" % inspect.stack()[1][3])
Exception: Timed out: test17_DFS_8Puzzle_03

test18_BFS_8Puzzle_01 (gradingtests.UnitTests)
Traceback (most recent call last):
  File "C:\Users\kille\academics\automatedgradingapp\app\testing\uninformed-solvers\gradingtests.py", line 52, in runPlayXSteps
    results = self.pool.apply_async(self.playXSteps, [solver, plays]).get(timeout)
  File "C:\Program Files\Python37\lib\multiprocessing\pool.py", line 679, in get
    raise TimeoutError
multiprocessing.context.TimeoutError

During handling of the above exception, another exception occurred:

Traceback (most recent call last):
  File "C:\Users\kille\academics\automatedgradingapp\app\testing\uninformed-solvers\gradingtests.py", line 390, in test18_BFS_8Puzzle_01
    [21, ((6, 5, 4), (1, -1, 8), (7, 3, 2))],
  File "C:\Users\kille\academics\automatedgradingapp\app\testing\uninformed-solvers\gradingtests.py", line 57, in runPlayXSteps
    raise Exception("Timed out: %s" % inspect.stack()[1][3])
Exception: Timed out: test18_BFS_8Puzzle_01

test19_BFS_8Puzzle_02 (gradingtests.UnitTests)
Traceback (most recent call last):
  File "C:\Users\kille\academics\automatedgradingapp\app\testing\uninformed-solvers\gradingtests.py", line 52, in runPlayXSteps
    results = self.pool.apply_async(self.playXSteps, [solver, plays]).get(timeout)
  File "C:\Program Files\Python37\lib\multiprocessing\pool.py", line 679, in get
    raise TimeoutError
multiprocessing.context.TimeoutError

During handling of the above exception, another exception occurred:

Traceback (most recent call last):
  File "C:\Users\kille\academics\automatedgradingapp\app\testing\uninformed-solvers\gradingtests.py", line 409, in test19_BFS_8Puzzle_02
    [6, ((5, 4, 8), (6, 1, 2), (7, 3, -1))],
  File "C:\Users\kille\academics\automatedgradingapp\app\testing\uninformed-solvers\gradingtests.py", line 57, in runPlayXSteps
    raise Exception("Timed out: %s" % inspect.stack()[1][3])
Exception: Timed out: test19_BFS_8Puzzle_02

test20_BFS_8Puzzle_03 (gradingtests.UnitTests)
Traceback (most recent call last):
  File "C:\Users\kille\academics\automatedgradingapp\app\testing\uninformed-solvers\gradingtests.py", line 52, in runPlayXSteps
    results = self.pool.apply_async(self.playXSteps, [solver, plays]).get(timeout)
  File "C:\Program Files\Python37\lib\multiprocessing\pool.py", line 679, in get
    raise TimeoutError
multiprocessing.context.TimeoutError

During handling of the above exception, another exception occurred:

Traceback (most recent call last):
  File "C:\Users\kille\academics\automatedgradingapp\app\testing\uninformed-solvers\gradingtests.py", line 428, in test20_BFS_8Puzzle_03
    [7, ((1, 2, -1), (8, 4, 3), (7, 6, 5))],
  File "C:\Users\kille\academics\automatedgradingapp\app\testing\uninformed-solvers\gradingtests.py", line 57, in runPlayXSteps
    raise Exception("Timed out: %s" % inspect.stack()[1][3])
Exception: Timed out: test20_BFS_8Puzzle_03

-------------------------------
TESTS FAILED  
test08_GM_8Puzzle_04 (gradingtests.UnitTests)
Traceback (most recent call last):
  File "C:\Users\kille\academics\automatedgradingapp\app\testing\uninformed-solvers\gradingtests.py", line 200, in test08_GM_8Puzzle_04
    self.assertEqual(p8.getGameState(), ((1,-1,3,),(8,2,4),(7,6,5)))
AssertionError: Tuples differ: ((1, 2, 3), (8, -1, 4), (7, 6, 5)) != ((1, -1, 3), (8, 2, 4), (7, 6, 5))

First differing element 0:
(1, 2, 3)
(1, -1, 3)

- ((1, 2, 3), (8, -1, 4), (7, 6, 5))
?      ^          ^^

+ ((1, -1, 3), (8, 2, 4), (7, 6, 5))
?      ^^          ^


-------------------------------
TESTS SKIPPED 
-------------------------------
